Traceback (most recent call last):
  File "/Users/ethan/opt/miniconda3/envs/pythonbook3/lib/python3.11/site-packages/jupyter_cache/executors/utils.py", line 58, in single_nb_execution
    executenb(
  File "/Users/ethan/opt/miniconda3/envs/pythonbook3/lib/python3.11/site-packages/nbclient/client.py", line 1305, in execute
    return NotebookClient(nb=nb, resources=resources, km=km, **kwargs).execute()
           ^^^^^^^^^^^^^^^^^^^^^^^^^^^^^^^^^^^^^^^^^^^^^^^^^^^^^^^^^^^^^^^^^^^^^
  File "/Users/ethan/opt/miniconda3/envs/pythonbook3/lib/python3.11/site-packages/jupyter_core/utils/__init__.py", line 166, in wrapped
    return loop.run_until_complete(inner)
           ^^^^^^^^^^^^^^^^^^^^^^^^^^^^^^
  File "/Users/ethan/opt/miniconda3/envs/pythonbook3/lib/python3.11/asyncio/base_events.py", line 653, in run_until_complete
    return future.result()
           ^^^^^^^^^^^^^^^
  File "/Users/ethan/opt/miniconda3/envs/pythonbook3/lib/python3.11/site-packages/nbclient/client.py", line 705, in async_execute
    await self.async_execute_cell(
  File "/Users/ethan/opt/miniconda3/envs/pythonbook3/lib/python3.11/site-packages/nbclient/client.py", line 1058, in async_execute_cell
    await self._check_raise_for_error(cell, cell_index, exec_reply)
  File "/Users/ethan/opt/miniconda3/envs/pythonbook3/lib/python3.11/site-packages/nbclient/client.py", line 914, in _check_raise_for_error
    raise CellExecutionError.from_cell_and_msg(cell, exec_reply_content)
nbclient.exceptions.CellExecutionError: An error occurred while executing the following cell:
------------------
a = list(margins)
a.mean()
------------------


[0;31m---------------------------------------------------------------------------[0m
[0;31mAttributeError[0m                            Traceback (most recent call last)
Cell [0;32mIn[10], line 2[0m
[1;32m      1[0m a [38;5;241m=[39m [38;5;28mlist[39m(margins)
[0;32m----> 2[0m [43ma[49m[38;5;241;43m.[39;49m[43mmean[49m()

[0;31mAttributeError[0m: 'list' object has no attribute 'mean'

