Traceback (most recent call last):
  File "/Users/ethan/opt/miniconda3/envs/pythonbook3/lib/python3.11/site-packages/jupyter_cache/executors/utils.py", line 58, in single_nb_execution
    executenb(
  File "/Users/ethan/opt/miniconda3/envs/pythonbook3/lib/python3.11/site-packages/nbclient/client.py", line 1305, in execute
    return NotebookClient(nb=nb, resources=resources, km=km, **kwargs).execute()
           ^^^^^^^^^^^^^^^^^^^^^^^^^^^^^^^^^^^^^^^^^^^^^^^^^^^^^^^^^^^^^^^^^^^^^
  File "/Users/ethan/opt/miniconda3/envs/pythonbook3/lib/python3.11/site-packages/jupyter_core/utils/__init__.py", line 166, in wrapped
    return loop.run_until_complete(inner)
           ^^^^^^^^^^^^^^^^^^^^^^^^^^^^^^
  File "/Users/ethan/opt/miniconda3/envs/pythonbook3/lib/python3.11/asyncio/base_events.py", line 653, in run_until_complete
    return future.result()
           ^^^^^^^^^^^^^^^
  File "/Users/ethan/opt/miniconda3/envs/pythonbook3/lib/python3.11/site-packages/nbclient/client.py", line 705, in async_execute
    await self.async_execute_cell(
  File "/Users/ethan/opt/miniconda3/envs/pythonbook3/lib/python3.11/site-packages/nbclient/client.py", line 1058, in async_execute_cell
    await self._check_raise_for_error(cell, cell_index, exec_reply)
  File "/Users/ethan/opt/miniconda3/envs/pythonbook3/lib/python3.11/site-packages/nbclient/client.py", line 914, in _check_raise_for_error
    raise CellExecutionError.from_cell_and_msg(cell, exec_reply_content)
nbclient.exceptions.CellExecutionError: An error occurred while executing the following cell:
------------------
Now we see that we can also get the names of the columns of our dataframe `tabs` by writing `tabs.columns`

------------------


[0;36m  Cell [0;32mIn[20], line 1[0;36m[0m
[0;31m    Now we see that we can also get the names of the columns of our dataframe `tabs` by writing `tabs.columns`[0m
[0m        ^[0m
[0;31mSyntaxError[0m[0;31m:[0m invalid syntax


