Traceback (most recent call last):
  File "/Users/ethan/opt/miniconda3/envs/pythonbook3/lib/python3.11/site-packages/jupyter_cache/executors/utils.py", line 58, in single_nb_execution
    executenb(
  File "/Users/ethan/opt/miniconda3/envs/pythonbook3/lib/python3.11/site-packages/nbclient/client.py", line 1305, in execute
    return NotebookClient(nb=nb, resources=resources, km=km, **kwargs).execute()
           ^^^^^^^^^^^^^^^^^^^^^^^^^^^^^^^^^^^^^^^^^^^^^^^^^^^^^^^^^^^^^^^^^^^^^
  File "/Users/ethan/opt/miniconda3/envs/pythonbook3/lib/python3.11/site-packages/jupyter_core/utils/__init__.py", line 166, in wrapped
    return loop.run_until_complete(inner)
           ^^^^^^^^^^^^^^^^^^^^^^^^^^^^^^
  File "/Users/ethan/opt/miniconda3/envs/pythonbook3/lib/python3.11/asyncio/base_events.py", line 653, in run_until_complete
    return future.result()
           ^^^^^^^^^^^^^^^
  File "/Users/ethan/opt/miniconda3/envs/pythonbook3/lib/python3.11/site-packages/nbclient/client.py", line 705, in async_execute
    await self.async_execute_cell(
  File "/Users/ethan/opt/miniconda3/envs/pythonbook3/lib/python3.11/site-packages/nbclient/client.py", line 1058, in async_execute_cell
    await self._check_raise_for_error(cell, cell_index, exec_reply)
  File "/Users/ethan/opt/miniconda3/envs/pythonbook3/lib/python3.11/site-packages/nbclient/client.py", line 914, in _check_raise_for_error
    raise CellExecutionError.from_cell_and_msg(cell, exec_reply_content)
nbclient.exceptions.CellExecutionError: An error occurred while executing the following cell:
------------------
import numpy as np
import seaborn as sns
from scipy import stats
from matplotlib import pyplot as plt

mu = 0
sigma = 1
x = np.linspace(mu - 3*sigma, mu + 3*sigma, 100)
y = 100* stats.norm.pdf(x, mu, sigma)

fig, axes = plt.subplots(1, 2, figsize=(15, 5))

sns.lineplot(x=x,y=y, color='black', ax=axes[0])
sns.lineplot(x=x,y=y, color='black', ax=axes[1])

axes[0].set_frame_on(False)
axes[1].set_frame_on(False)
axes[0].get_yaxis().set_visible(False)
axes[1].get_yaxis().set_visible(False)
axes[0].get_xaxis().set_visible(False)
axes[1].get_xaxis().set_visible(False)

axes[0].axhline(y=0, color='black')
axes[0].axvline(x=mu, color='black', linestyle='--')

axes[1].axhline(y=0, color='black')
axes[1].axvline(x=mu + sigma, color='black', linestyle='--')

axes[0].hlines(y=23.6, xmin = mu-sigma, xmax = mu, color='black')
axes[1].hlines(y=23.6, xmin = mu-sigma, xmax = mu, color='black')


axes[0].text(mu,42, r'$\mu = \mu_0$', size=20, ha="center")
axes[1].text(mu + sigma, 42, r'$\mu \neq \mu_0$', size=20, ha="center")

axes[0].text(mu-sigma - 0.2, 23.6, r'$\sigma = \sigma_0$', size=20, ha="right")
axes[1].text(mu-sigma - 0.2, 23.6, r'$\sigma = \sigma_0$', size=20, ha="right")


glue("ztesthyp-fig", ax, display=False)
------------------


[0;31m---------------------------------------------------------------------------[0m
[0;31mNameError[0m                                 Traceback (most recent call last)
Cell [0;32mIn[4], line 40[0m
[1;32m     36[0m axes[[38;5;241m0[39m][38;5;241m.[39mtext(mu[38;5;241m-[39msigma [38;5;241m-[39m [38;5;241m0.2[39m, [38;5;241m23.6[39m, [38;5;124mr[39m[38;5;124m'[39m[38;5;124m$[39m[38;5;124m\[39m[38;5;124msigma = [39m[38;5;124m\[39m[38;5;124msigma_0$[39m[38;5;124m'[39m, size[38;5;241m=[39m[38;5;241m20[39m, ha[38;5;241m=[39m[38;5;124m"[39m[38;5;124mright[39m[38;5;124m"[39m)
[1;32m     37[0m axes[[38;5;241m1[39m][38;5;241m.[39mtext(mu[38;5;241m-[39msigma [38;5;241m-[39m [38;5;241m0.2[39m, [38;5;241m23.6[39m, [38;5;124mr[39m[38;5;124m'[39m[38;5;124m$[39m[38;5;124m\[39m[38;5;124msigma = [39m[38;5;124m\[39m[38;5;124msigma_0$[39m[38;5;124m'[39m, size[38;5;241m=[39m[38;5;241m20[39m, ha[38;5;241m=[39m[38;5;124m"[39m[38;5;124mright[39m[38;5;124m"[39m)
[0;32m---> 40[0m [43mglue[49m([38;5;124m"[39m[38;5;124mztesthyp-fig[39m[38;5;124m"[39m, ax, display[38;5;241m=[39m[38;5;28;01mFalse[39;00m)

[0;31mNameError[0m: name 'glue' is not defined

